Workbook
Name _30_Jun_13: [1]ESTIMATES!$A$4
Name current_price: [2]KeyData!$B$13
Name dcf_discount: DCF!$B$5
Name dcf_mos: '[2]DCF Valuation'!$E$3
Name Estiamtes: #REF!
Name ESTIMATES: [1]ESTIMATES!$A$1
Name FCFE_growth: [2]DCFData!$H$81
Name FCFF_growth: [2]DCFData!$H$82
Name graham_eps: #REF!
Name list_discount: [2]Lists!$E$2:$E$7
Name list_graham_sensitivity: [2]Lists!$M$2:$M$5
Name list_terminal: [2]Lists!$G$2:$G$9
Name user_discount: DCF!$B$6
Name user_fcf: DCF!$E$5
Name user_graham_growth: #REF!
Name user_growth: DCF!$G$5
Name WACC: WACC!$C$40

Sheet Company Profile
A1: Address | B1: Kelvin Road North/Cripps Road, Graniteside, Box GT942
B2: Harare, Zimbabwe
A3: Industry | B3: Electronic & Electrical Equipment
A5: Sector | B5: Industrials
A7: Senior Management | B7: HILTION MACKLIN
B8: Manging Director
B9: MARTIN GURIRA
B10: Operations Director & Group Secretary
A14: Company description | B14: Powerspeed Electrical is a leading supplier of electrical, hardware, building and home improvement products and services; trading through its own chain of hardware retail outlets known as Electrosales Hardware. The company supplies electrical products and solutions to the painting, plumbing, electrical, building, hand and power tools, outdoor and gardening, and automotive industries in Zimbabwe.

Sheet Financials HY
B1: June | C1: June | D1: June | E1: June | F1: June | G1: June | H1: June | I1: June
B2: 2017 | C2: 2018 | D2: 2019 | E2: 2020 | F2: 2021 | G2: 2022 | H2: 2023 | I2: 2024
A3: Revenue | C3: 17948319 | D3: 320682914 | E3: 1376518853 | F3: =6321175173 -> 6321175173 | G3: 47635606205 | H3: 24148941 | I3: 31510454
A4: Cost of sales
A5: Gross Profit
A6: Operating expenses
A7: Other operating income
A8: Other expenses
A9: EBITDA | C9: 914453 | D9: 85393209 | E9: 826342145 | F9: 1714448051 | G9: 14118589191 | H9: 2637174 | I9: 7269383
A10: Other income | C10: 202041 | D10: 0 | E10: 0 | F10: 0 | G10: 0 | H10: 0 | I10: 0
A11: Fair value adjustments | D11: 57971722 | G11: 12044759748 | H11: 0 | I11: 0
A12: Depreciation | D12: -16562305 | E12: -83442834 | F12: -233337964 | G12: -1375215691 | H12: -740093 | I12: -2232633
A13: EBIT | C13: 690502 | D13: =SUM(D9:D12) -> 126802626 | E13: =SUM(E9:E12) -> 742899311 | F13: =SUM(F9:F12) -> 1481110087 | G13: =SUM(G9:G12) -> 24788133248 | H13: =SUM(H9:H12) -> 1897081 | I13: =SUM(I9:I12) -> 5036750
A14: Reclassfication of foreign currency translation reserve
A15: Fair value adjustments | E15: 93397843 | H15: 2200
A16: Net monetory gain | E16: -468751991 | F16: -154275369 | G16: 1861396121 | H16: 2801682 | I16: 0
A17: Finance costs | C17: -90061 | D17: -795237 | E17: -3222233 | F17: -59927147 | G17: -379053344 | H17: -120697 | I17: -158659
A18: Income Before Tax (EBT) | C18: =SUM(C13:C17) -> 600441 | D18: =SUM(D13:D17) -> 126007389 | E18: =SUM(E13:E17) -> 364322930 | F18: =SUM(F13:F17) -> 1266907571 | G18: =SUM(G13:G17) -> 26270476025 | H18: =SUM(H13:H17) -> 4580266 | I18: =SUM(I13:I17) -> 4878091
A19: Tax | C19: -67842 | D19: -6122882 | E19: -111410791 | F19: -415479238 | G19: -3889336867 | H19: -1132242 | I19: -1253687
A20: Profit from continuing operations | C20: =SUM(C18:C19) -> 532599 | D20: =SUM(D18:D19) -> 119884507 | E20: =SUM(E18:E19) -> 252912139 | F20: =SUM(F18:F19) -> 851428333 | G20: =SUM(G18:G19) -> 22381139158 | H20: =SUM(H18:H19) -> 3448024 | I20: =SUM(I18:I19) -> 3624404
A21: Tax rate | C21: =C19/C18 -> -0.11298695 | D21: =D19/D18 -> -0.048591452 | E21: =E19/E18 -> -0.3058023 | F21: =F19/F18 -> -0.32794755 | G21: =G19/G18 -> -0.14804973 | H21: =-H19/H18 -> 0.24720005 | I21: =-I19/I18 -> 0.25700361
A23: BALANCE SHEET | C23: =C1 -> June | D23: =D1 -> June | E23: =E1 -> June | F23: =F1 -> June | G23: =G1 -> June | H23: =H1 -> June | I23: =I1 -> June
C24: =C2 -> 2018 | D24: =D2 -> 2019 | E24: =E2 -> 2020 | F24: =F2 -> 2021 | G24: =G2 -> 2022 | H24: =H2 -> 2023 | I24: =I2 -> 2024
A25: PPE | C25: 8691388 | D25: 442451689 | E25: 1185122316 | F25: 4719400769 | G25: 57875390570 | H25: 23630406 | I25: 21568656
A26: Deferred tax asset
A27: Investment in Property | C27: 4616000 | D27: 171367608 | E27: 487211857 | F27: 3133405427 | G27: 28444264032 | H27: 7800930 | I27: 7800930
A28: Intangible asset
A29: Investments | C29: 2795681 | D29: 31321964 | E29: 195797383 | F29: 326985199 | G29: 624049792 | H29: 78304 | I29: 44688
A30: Total Non current Assets | C30: =SUM(C25:C29) -> 16103069 | D30: =SUM(D25:D29) -> 645141261 | E30: =SUM(E25:E29) -> 1868131556 | F30: =SUM(F25:F29) -> 8179791395 | G30: =SUM(G25:G29) -> 86943704394 | H30: =SUM(H25:H29) -> 31509640 | I30: =SUM(I25:I29) -> 29414274
A31: Current Assets
A32: Inventories | C32: 1725984 | D32: 75162374 | E32: 142152818 | F32: 406327543 | G32: 1473577727 | H32: 4580974 | I32: 4454927
A33: Prepayment and deposits
A34: Trade and other receivables
A35: Contracts in progress and contracts receivables | C35: 20357440 | D35: 451781602 | E35: 3299646475 | F35: 12524656727 | G35: 90769319905 | H35: 46962352 | I35: 43607531
A36: Short term investments
A37: Tax Assets | C37: 78579 | D37: 0 | E37: 0 | F37: 0 | G37: 0 | H37: 0 | I37: 0
A38: Cash and equivalents | C38: 3788881 | D38: 30982916 | E38: 287137113 | F38: 3851755397 | G38: 4463107397 | H38: 2731700 | I38: 2165459
A39: Assets classified as held for sale
A40: Loans
A41: Total Current Assets | C41: =SUM(C32:C40) -> 25950884 | D41: =SUM(D32:D40) -> 557926892 | E41: =SUM(E32:E40) -> 3728936406 | F41: =SUM(F32:F40) -> 16782739667 | G41: =SUM(G32:G40) -> 96706005029 | H41: =SUM(H32:H40) -> 54275026 | I41: =SUM(I32:I40) -> 50227917
...

Sheet Quarters
D2: 2018 | E2: Q2 | F2: Q3
C3: Revenue | D3: ='Financials FY'!L3 -> 248549590 | E3: ='Financials HY'!D3 -> 320682914 | F3: 76389003 | J3: 17948319 | K3: =(D3-J3)/2 -> 1.1530064e+08 | L3: =K3+J3 -> 1.3324895e+08 | M3: =(F3-L3)/L3 -> -0.42671968
C4: EBITDA | F4: 19097251
C5: EBIT
C6: EbitMargin | F6: =F4/F3 -> 0.25

Sheet Data Input
A1: OTHER COMPANIES | B1: FY2012 | C1: FY2013 | D1: FY2014 | E1: FY2015 | F1: FY2016 | G1: FY2017 | H1: FY2018 | I1: FY2019 | J1: FY2020 | K1: FY2021 | L1: FY2022 | M1: FY2023 | N1: FY2024F
P2: RATINGS BACKGROUND CALCULATIONS | S2: Share PRICE PROFILE METRICS
A3: intangible assets | D3: ='Financials FY'!H45 -> 0 | E3: ='Financials FY'!I45 -> 0 | F3: ='Financials FY'!J45 -> 0 | G3: ='Financials FY'!K42 -> 8727868 | H3: ='Financials FY'!L42 -> 53986552 | I3: ='Financials FY'!M42 -> 757571799 | J3: ='Financials FY'!N42 -> 1578414353 | K3: ='Financials FY'!O42 -> 7410742000 | L3: ='Financials FY'!P42 -> 19944208 | M3: ='Financials FY'!Q42 -> 23630406
A4: Adjusted book value | C4: ='Financials FY'!G71 -> 0 | D4: ='Financials FY'!H71 -> 20112053 | E4: ='Financials FY'!I71 -> 11790662 | F4: ='Financials FY'!J71 -> 12311543 | G4: ='Financials FY'!K71 -> 14038405 | H4: ='Financials FY'!L71 -> 102795573 | I4: ='Financials FY'!M71 -> 1162729925 | J4: ='Financials FY'!N71 -> 2674849654 | ... M4: ='Financials FY'!Q71 -> 24227135 | S4: Price | T4: =M12 -> 11
A5: Interest expense | C5: =-('Financials FY'!G13+'Financials FY'!G16) -> 0 | D5: =-('Financials FY'!H13+'Financials FY'!H16) -> 344253 | E5: =-('Financials FY'!I13+'Financials FY'!I16) -> 82569 | F5: =-('Financials FY'!J13+'Financials FY'!J16) -> 39621 | G5: =-('Financials FY'!K13+'Financials FY'!K16) -> 117448 | H5: =-('Financials FY'!L13+'Financials FY'!L16) -> 1070216 | I5: =-('Financials FY'!M13+'Financials FY'!M16) -> 4265353 | J5: =-('Financials FY'!N13+'Financials FY'!N16) -> 12987289 | ... M5: =-('Financials FY'!Q13+'Financials FY'!Q16) -> 363607 | P5: DCF | Q5: =M9 -> 1.0869176 | S5: Change from previous day | T5: =T4-T7 -> 11
A6: Capex | C6: =-'Financials FY'!G121 -> 0 | D6: =-'Financials FY'!H121 -> 0 | E6: =-'Financials FY'!I121 -> 135586 | F6: =-'Financials FY'!J121 -> 1765204 | G6: =-'Financials FY'!K121 -> 2920223 | H6: =-'Financials FY'!L121 -> 1633551 | I6: =-'Financials FY'!M121 -> 589737378 | J6: =-'Financials FY'!N121 -> 492532971 | ... M6: =-'Financials FY'!Q121 -> 4150995 | P6: Price | Q6: =M12 -> 11 | S6: Percentage change (%) | T6: =T5/T7 -> #DIV/0!
A7: Gross profit | C7: ='Financials FY'!G5 -> 0 | D7: ='Financials FY'!H5 -> 14848743 | E7: ='Financials FY'!I5 -> 10039549 | F7: ='Financials FY'!J5 -> 19139918 | G7: ='Financials FY'!K5 -> 4197192 | H7: ='Financials FY'!L5 -> 0 | I7: ='Financials FY'!M5 -> 1498657461 | J7: ='Financials FY'!N5 -> 8390738256 | ... M7: ='Financials FY'!Q5 -> 53834005 | P7: Price/Earnings Ratio (P/E) | Q7: =(M12*M18/(100*M15)) -> 3.4875833 | S7: Prev Close | T7: =M13 -> 0
P8: P/E (Forward) | Q8: =(M12*M18/(100*N14)) -> 3.4875833 | S8: 52 Week Range
A9: DCF | E9: =F9 -> 1.0869176 | F9: =G9 -> 1.0869176 | G9: =I9 -> 1.0869176 | H9: =K9 -> 0 | I9: =M9 -> 1.0869176 | J9: =N9 -> 9.0470364 | K9: =O9 -> 0 | L9: =P9 -> Price/NAV | M9: =Q9 -> 1.0869176 | N9: =DCF!C40 -> 9.0470364 | P9: Price/NAV | Q9: =(M12*M18)/((M17))/100 -> 1.0869176 | S9: PE Ratio | T9: =Q7 -> 3.4875833
A10: Earnings before interest and tax (EBIT) | C10: ='Financials FY'!G10 -> 0 | D10: ='Financials FY'!H10 -> -936437 | E10: ='Financials FY'!I10 -> -1354722 | F10: ='Financials FY'!J10 -> -2685172 | G10: ='Financials FY'!K10 -> -2946075 | H10: ='Financials FY'!L10 -> 11596451 | I10: ='Financials FY'!M10 -> 402731168 | J10: ='Financials FY'!N10 -> 1567387720 | ... M10: ='Financials FY'!Q10 -> 8237104 | N10: =M10*(1+DCF!L13) -> 8237104 | P10: EV/EBIT | Q10: =M36/M10 -> 2.5897812 | S10: Forward PE: | T10: =Q8 -> 3.4875833
P11: P/OP cashflow | Q11: =(M12*M18/(100*M23)) -> 5.28917 | S11: ROE | T11: =Q25 -> 0.31165352
A12: Share Price (cents) | D12: ='Financials FY'!H130 -> 0 | E12: ='Financials FY'!I130 -> 0.81 | F12: ='Financials FY'!J130 -> 1.7 | G12: ='Financials FY'!K130 -> 7.2 | H12: ='Financials FY'!L130 -> 7.56 | I12: ='Financials FY'!M130 -> 48 | J12: ='Financials FY'!N130 -> 4001.38 | K12: ='Financials FY'!O130 -> 7000 | ... M12: ='Financials FY'!Q130 -> 11 | P12: Net profit growth | Q12: =(M15-I15)/I15 -> -0.95091717 | S12: ROA | T12: =Q26 -> 0.092055552
A13: Share price (previous day closing price) | P13: Net profit growth (F) | Q13: =(N15-M15)/M15 -> 0 | S13: EPS | T13: =Q18*100 -> 3.1540465
A14: Earnings attributable for shareholders | C14: ='Financials FY'!G25 -> 0 | D14: ='Financials FY'!H25 -> -1033304 | E14: ='Financials FY'!I25 -> -834961 | F14: ='Financials FY'!J25 -> -2804842 | G14: ='Financials FY'!K25 -> -3498454 | H14: ='Financials FY'!L25 -> 9167385 | I14: ='Financials FY'!M25 -> 153831213 | J14: ='Financials FY'!N25 -> 526238344 | ... M14: ='Financials FY'!Q25 -> 7550472 | N14: =M14*(1+DCF!L13) -> 7550472 | P14: Cash generated from operations growth | Q14: =(M23-I23)/I23 -> -0.99155727 | S14: P/NAV | T14: =Q9 -> 1.0869176
A15: Net profit | C15: ='Financials FY'!G19 -> 0 | D15: ='Financials FY'!H19 -> -1033304 | E15: ='Financials FY'!I19 -> -834961 | F15: ='Financials FY'!J19 -> -2804842 | G15: ='Financials FY'!K19 -> -3498454 | H15: ='Financials FY'!L19 -> 9167385 | I15: ='Financials FY'!M19 -> 153831213 | J15: ='Financials FY'!N19 -> 526238344 | ... M15: ='Financials FY'!Q19 -> 7550472 | N15: =M15*(1+DCF!L13) -> 7550472 | S15: DCF | T15: =DCF!C38 -> 21657700
A16: Revenue | D16: ='Financials FY'!H3 -> 14848743 | E16: ='Financials FY'!I3 -> 10039549 | F16: ='Financials FY'!J3 -> 19139918 | G16: ='Financials FY'!K3 -> 27451196 | H16: ='Financials FY'!L3 -> 248549590 | I16: ='Financials FY'!M3 -> 1498657461 | J16: ='Financials FY'!N3 -> 8390738256 | K16: ='Financials FY'!O3 -> 25284481000 | ... M16: ='Financials FY'!Q3 -> 53834005 | N16: =DCF!B16 -> 57112496 | P16: Revenue growth | Q16: =(M16-I16)/I16 -> -0.96407851 | S16: Market Cap | T16: =Q24 -> 26332900
A17: Equity | C17: ='Financials FY'!G71 -> 0 | D17: ='Financials FY'!H71 -> 20112053 | E17: ='Financials FY'!I71 -> 11790662 | F17: ='Financials FY'!J71 -> 12311543 | G17: ='Financials FY'!K71 -> 14038405 | H17: ='Financials FY'!L71 -> 102795573 | I17: ='Financials FY'!M71 -> 1162729925 | J17: ='Financials FY'!N71 -> 2674849654 | ... M17: ='Financials FY'!Q71 -> 24227135 | P17: Revenue growth (F) | Q17: =(N16-M16)/M16 -> 0.0609 | S17: NAV | T17: =M38 -> 27818259
A18: Issued Shares | D18: ='Financials FY'!H131 -> 0 | E18: ='Financials FY'!I131 -> 220493732 | F18: ='Financials FY'!J131 -> 220493732 | G18: ='Financials FY'!K131 -> 232019894 | H18: ='Financials FY'!L131 -> 233182394 | I18: ='Financials FY'!M131 -> 241653707 | J18: ='Financials FY'!N131 -> 241653707 | K18: ='Financials FY'!O131 -> 241653707 | ... M18: ='Financials FY'!Q131 -> 239390000 | P18: EPS | Q18: =M14/M18 -> 0.031540465 | S18: Issued Shares | T18: =M18 -> 239390000
A19: Cash and bank balances | D19: ='Financials FY'!H55 -> 1729139 | E19: ='Financials FY'!I55 -> 737173 | F19: ='Financials FY'!J55 -> 780267 | G19: ='Financials FY'!K55 -> 1294967 | H19: ='Financials FY'!L55 -> 23534630 | I19: ='Financials FY'!M55 -> 53049371 | J19: ='Financials FY'!N55 -> 382425791 | K19: ='Financials FY'!O55 -> 6048304000 | ... M19: ='Financials FY'!Q55 -> 2731700 | P19: EBIT growth | Q19: =(M10-K10)/K10 -> -0.99823368 | S19: NB: all per share metrics are in cents
A20: Minority interest | D20: ='Financials FY'!H70 -> 0 | E20: ='Financials FY'!I70 -> 0 | F20: ='Financials FY'!J70 -> 0 | G20: ='Financials FY'!K70 -> 0 | H20: ='Financials FY'!L70 -> 0 | I20: ='Financials FY'!M70 -> 0 | J20: ='Financials FY'!N70 -> 0 | K20: ='Financials FY'!O70 -> 0 | ... M20: ='Financials FY'!Q70 -> 0 | P20: EBIT growth (F) | Q20: =(N10-M10)/M10 -> 0
A21: Preferred shares | P21: FCF growth | Q21: =(M33-I33)/I33 -> -21.147274 | S21: FINANCIALS SUMMARY
A22: Net Operating cashflow | D22: ='Financials FY'!H97 -> 1969797 | E22: ='Financials FY'!I97 -> 1969797 | F22: ='Financials FY'!J97 -> 591511 | G22: ='Financials FY'!K97 -> 2265802 | H22: ='Financials FY'!L97 -> 20072981 | I22: ='Financials FY'!M97 -> 589696298 | J22: ='Financials FY'!N97 -> 615874311 | K22: ='Financials FY'!O97 -> 8721813000 | ... M22: ='Financials FY'!Q97 -> 4978645 | S22: INCOME STATEMENT | T22: =F1 -> FY2016 | U22: =G1 -> FY2017 | V22: =H1 -> FY2018 | W22: =I1 -> FY2019 | X22: =J1 -> FY2020 | Y22: =K1 -> FY2021 | Z22: =L1 -> FY2022 | AA22: =M1 -> FY2023
A23: Cash generated from operations | C23: ='Financials FY'!G92 -> 0 | D23: ='Financials FY'!H92 -> 1969797 | E23: ='Financials FY'!I92 -> 1633461 | F23: ='Financials FY'!J92 -> 553165 | G23: ='Financials FY'!K92 -> 2383250 | H23: ='Financials FY'!L92 -> 20072981 | I23: ='Financials FY'!M92 -> 589696298 | J23: ='Financials FY'!N92 -> 615874311 | ... M23: ='Financials FY'!Q92 -> 4978645 | P23: Net cash inflow from operations per share | Q23: =M22/M18*100 -> 2.0797214 | S23: Revenue | T23: =F16 -> 19139918 | U23: =G16 -> 27451196 | V23: =H16 -> 248549590 | W23: =I16 -> 1498657461 | X23: =J16 -> 8390738256 | Y23: =K16 -> 25284481000 | Z23: =L16 -> 49818414 | AA23: =M16 -> 53834005
A24: Current assets | D24: ='Financials FY'!H58 -> 17418677 | E24: ='Financials FY'!I58 -> 9874579 | F24: ='Financials FY'!J58 -> 11924380 | G24: ='Financials FY'!K58 -> 17666048 | H24: ='Financials FY'!L58 -> 161193886 | I24: ='Financials FY'!M58 -> 955290015 | J24: ='Financials FY'!N58 -> 4966412877 | K24: ='Financials FY'!O58 -> 26353465000 | ... M24: ='Financials FY'!Q58 -> 54275026 | P24: Market Capitalisation | Q24: =M18*M12/100 -> 26332900 | S24: Gross Profit | T24: =F7 -> 19139918 | U24: =G7 -> 4197192 | V24: =H7 -> 0 | W24: =I7 -> 1498657461 | X24: =J7 -> 8390738256 | Y24: =K7 -> 25284481000 | Z24: =L7 -> 49818414 | AA24: =M7 -> 53834005
A25: Current liabilities | D25: ='Financials FY'!H86 -> 11033528 | E25: ='Financials FY'!I86 -> 7967258 | F25: ='Financials FY'!J86 -> 10564576 | G25: ='Financials FY'!K86 -> 15929669 | H25: ='Financials FY'!L86 -> 140240986 | I25: ='Financials FY'!M86 -> 638338362 | J25: ='Financials FY'!N86 -> 4235153252 | K25: ='Financials FY'!O86 -> 24618756000 | ... M25: ='Financials FY'!Q86 -> 53695885 | P25: ROE | Q25: =M14/M17 -> 0.31165352 | S25: EBIT | T25: =F10 -> -2685172 | U25: =G10 -> -2946075 | V25: =H10 -> 11596451 | W25: =I10 -> 402731168 | X25: =J10 -> 1567387720 | Y25: =K10 -> 4663423000 | Z25: =L10 -> 12367050 | AA25: =M10 -> 8237104
A26: Non current liabilities | C26: ='Financials FY'!G77 -> 0 | D26: ='Financials FY'!H77 -> 2823600 | E26: ='Financials FY'!I77 -> 1286033 | F26: ='Financials FY'!J77 -> 1566298 | G26: ='Financials FY'!K77 -> 3188102 | H26: ='Financials FY'!L77 -> 18181525 | I26: ='Financials FY'!M77 -> 258841370 | J26: ='Financials FY'!N77 -> 544495477 | ... M26: ='Financials FY'!Q77 -> 7861646 | P26: ROA | Q26: =M10*(1-M37)/(M32+M24) -> 0.092055552 | S26: Net Profit | T26: =F15 -> -2804842 | U26: =G15 -> -3498454 | V26: =H15 -> 9167385 | W26: =I15 -> 153831213 | X26: =J15 -> 526238344 | Y26: =K15 -> 3386459000 | Z26: =L15 -> 12400715 | AA26: =M15 -> 7550472
A27: Trade Receivables | D27: ='Financials FY'!H51 -> 0 | E27: ='Financials FY'!I51 -> 1957829 | F27: ='Financials FY'!J51 -> 3579559 | G27: ='Financials FY'!K51 -> 5372084 | H27: ='Financials FY'!L51 -> 0 | I27: ='Financials FY'!M51 -> 0 | J27: ='Financials FY'!N51 -> 0 | K27: ='Financials FY'!O51 -> 0 | ... M27: ='Financials FY'!Q51 -> 0 | P27: ROIC | Q27: =(M10*(1-M37)/(M31+M30+M17-M34)) -> 0.33782345
A28: Cost of Sales | C28: =-'Financials FY'!G4 -> 0 | D28: =-'Financials FY'!H4 -> 0 | E28: =-'Financials FY'!I4 -> 0 | F28: =-'Financials FY'!J4 -> 0 | G28: =-'Financials FY'!K4 -> 23254004 | H28: =-'Financials FY'!L4 -> -248549590 | I28: =-'Financials FY'!M4 -> 0 | J28: =-'Financials FY'!N4 -> 0 | ... M28: =-'Financials FY'!Q4 -> 0 | P28: Net margin | Q28: =M15/M16 -> 0.1402547 | S28: CASHFLOW STATEMENT | T28: =T22 -> FY2016 | U28: =U22 -> FY2017 | V28: =V22 -> FY2018 | W28: =W22 -> FY2019 | X28: =X22 -> FY2020 | Y28: =Y22 -> FY2021 | Z28: =Z22 -> FY2022 | AA28: =AA22 -> FY2023
A29: Total Inventory | C29: ='Financials FY'!G49 -> 0 | D29: ='Financials FY'!H49 -> 5365107 | E29: ='Financials FY'!I49 -> 400472 | F29: ='Financials FY'!J49 -> 954819 | G29: ='Financials FY'!K49 -> 1200575 | H29: ='Financials FY'!L49 -> 10720948 | I29: ='Financials FY'!M49 -> 128694039 | J29: ='Financials FY'!N49 -> 189327333 | ... M29: ='Financials FY'!Q49 -> 4580974 | P29: Management | S29: Net cashflow from operations | T29: =F22 -> 591511 | U29: =G22 -> 2265802 | V29: =H22 -> 20072981 | W29: =I22 -> 589696298 | X29: =J22 -> 615874311 | Y29: =K22 -> 8721813000 | Z29: =L22 -> 771971 | AA29: =M22 -> 4978645
A30: Short term debt | D30: ='Financials FY'!H81+'Financials FY'!H83 -> 1166667 | E30: ='Financials FY'!I81+'Financials FY'!I83 -> 222267 | F30: ='Financials FY'!J81+'Financials FY'!J83 -> 390267 | G30: ='Financials FY'!K81+'Financials FY'!K83 -> 489995 | H30: ='Financials FY'!L81+'Financials FY'!L83 -> 7191467 | I30: ='Financials FY'!M81+'Financials FY'!M83 -> 9713506 | J30: ='Financials FY'!N81+'Financials FY'!N83 -> 167426274 | K30: ='Financials FY'!O81+'Financials FY'!O83 -> 1138874000 | ... M30: ='Financials FY'!Q81+'Financials FY'!Q83 -> 1880547 | P30: Receivables turnover % change | Q30: =((M16*2/(M27+I27))-(I16*2/(I27+M27)))/((I16*2/(I27+M27))) -> #DIV/0! | S30: Cash and cash equivalents | T30: =F19 -> 780267 | U30: =G19 -> 1294967 | V30: =H19 -> 23534630 | W30: =I19 -> 53049371 | X30: =J19 -> 382425791 | Y30: =K19 -> 6048304000 | Z30: =L19 -> 1538014 | AA30: =M19 -> 2731700
A31: Long term debt | C31: ='Financials FY'!G76+'Financials FY'!G75 -> 0 | D31: ='Financials FY'!H76+'Financials FY'!H75 -> 416667 | E31: ='Financials FY'!I76+'Financials FY'!I75 -> 222268 | F31: ='Financials FY'!J76+'Financials FY'!J75 -> 315567 | G31: ='Financials FY'!K76+'Financials FY'!K75 -> 1409130 | H31: ='Financials FY'!L76+'Financials FY'!L75 -> 3818246 | I31: ='Financials FY'!M76+'Financials FY'!M75 -> 11434433 | J31: ='Financials FY'!N76+'Financials FY'!N75 -> 40379961 | ... M31: ='Financials FY'!Q76+'Financials FY'!Q75 -> 0 | P31: Inventory turnover % change | Q31: =((I28*2/(I29+G29))-(G28*2/(G29+F29)))/(G28*2/(G29+F29)) -> -1 | S31: Free cashflow | T31: =F33 -> -1173693 | U31: =G33 -> -654421 | V31: =H33 -> 18439430 | W31: =I33 -> -41080 | X31: =J33 -> 123341340 | Y31: =K33 -> 4785081000 | Z31: =L33 -> -3974724 | AA31: =M33 -> 827650
A32: Non current assets | D32: ='Financials FY'!H47 -> 16550504 | E32: ='Financials FY'!I47 -> 11169374 | F32: ='Financials FY'!J47 -> 12518037 | G32: ='Financials FY'!K47 -> 15490128 | H32: ='Financials FY'!L47 -> 100024198 | I32: ='Financials FY'!M47 -> 1104619642 | J32: ='Financials FY'!N47 -> 2488085506 | K32: ='Financials FY'!O47 -> 12844496000 | ... M32: ='Financials FY'!Q47 -> 31509640 | P32: Debt ratio | Q32: =(M30+M31)/(M24+M32) -> 0.021921715 | S32: Capex | T32: =F6 -> 1765204 | U32: =G6 -> 2920223 | V32: =H6 -> 1633551 | W32: =I6 -> 589737378 | X32: =J6 -> 492532971 | Y32: =K6 -> 3936732000 | Z32: =L6 -> 4746695 | AA32: =M6 -> 4150995
A33: Free Cash Flow | D33: ='Financials FY'!H126 -> 1969797 | E33: ='Financials FY'!I126 -> 1834211 | F33: ='Financials FY'!J126 -> -1173693 | G33: ='Financials FY'!K126 -> -654421 | H33: ='Financials FY'!L126 -> 18439430 | I33: ='Financials FY'!M126 -> -41080 | J33: ='Financials FY'!N126 -> 123341340 | K33: ='Financials FY'!O126 -> 4785081000 | ... M33: ='Financials FY'!Q126 -> 827650 | P33: Total Asset Turnover % change | Q33: =((2*I16/(I32+I24+G24+G32))-(2*G16/(G32+G24+F24+F32)))/(2*G16/(G32+G24+F24+F32)) -> 0.50234645
A34: Cash balances | C34: ='Financials FY'!G55 -> 0 | D34: ='Financials FY'!H55 -> 1729139 | E34: ='Financials FY'!I55 -> 737173 | F34: ='Financials FY'!J55 -> 780267 | G34: ='Financials FY'!K55 -> 1294967 | H34: ='Financials FY'!L55 -> 23534630 | I34: ='Financials FY'!M55 -> 53049371 | J34: ='Financials FY'!N55 -> 382425791 | ... M34: ='Financials FY'!Q55 -> 2731700 | P34: Interest Cover ratio | Q34: =M10/M5 -> 22.653865 | S34: BALANCE SHEET | T34: =T28 -> FY2016 | U34: =U28 -> FY2017 | V34: =V28 -> FY2018 | W34: =W28 -> FY2019 | X34: =X28 -> FY2020 | Y34: =Y28 -> FY2021 | Z34: =Z28 -> FY2022 | AA34: =AA28 -> FY2023
A35: Dividend | D35: 0 | E35: 0 | F35: 0 | G35: 0 | H35: 1 | I35: 2 | J35: 3 | K35: 4 | L35: 5 | M35: 6 | P35: ST debt % of current assets | Q35: =M30/M24 -> 0.034648477 | S35: Non Current Assets | T35: =F32 -> 12518037 | U35: =G32 -> 15490128 | V35: =H32 -> 100024198 | W35: =I32 -> 1104619642 | X35: =J32 -> 2488085506 | Y35: =K32 -> 12844496000 | Z35: =L32 -> 29961324 | AA35: =M32 -> 31509640
A36: Enterprise value (EV) | D36: ='Financials FY'!H134+'Financials FY'!H81+'Financials FY'!H76-'Financials FY'!H55 -> -145805 | E36: ='Financials FY'!I134+'Financials FY'!I81+'Financials FY'!I76-'Financials FY'!I55 -> 1493361.2 | F36: ='Financials FY'!J134+'Financials FY'!J81+'Financials FY'!J76-'Financials FY'!J55 -> 3673960.4 | G36: ='Financials FY'!K134+'Financials FY'!K81+'Financials FY'!K76-'Financials FY'!K55 -> 16526318 | H36: ='Financials FY'!L134+'Financials FY'!L81+'Financials FY'!L76-'Financials FY'!L55 -> -658213.01 | I36: ='Financials FY'!M134+'Financials FY'!M81+'Financials FY'!M76-'Financials FY'!M55 -> 82151537 | J36: ='Financials FY'!N134+'Financials FY'!N81+'Financials FY'!N76-'Financials FY'!N55 -> 9.4947966e+09 | K36: ='Financials FY'!O134+'Financials FY'!O81+'Financials FY'!O76-'Financials FY'!O55 -> 12006329490 | L36: ='Financials FY'!P134+'Financials FY'!P81+'Financials FY'!P76-'Financials FY'!P55 -> 25500054 | M36: ='Financials HY'!I75+'Financials HY'!I64-'Financials HY'!I38 -> 21332297 | P36: Current ratio | Q36: =M24/M25 -> 1.0107856 | S36: Current Assets | T36: =F24 -> 11924380 | U36: =G24 -> 17666048 | V36: =H24 -> 161193886 | W36: =I24 -> 955290015 | X36: =J24 -> 4966412877 | Y36: =K24 -> 26353465000 | Z36: =L24 -> 33325474 | AA36: =M24 -> 54275026
A37: Tax Rate | D37: ='Financials FY'!H39 -> 0.71455246 | E37: ='Financials FY'!I39 -> 0.5277223 | F37: ='Financials FY'!J39 -> -0.072267647 | G37: ='Financials FY'!K39 -> -0.15727006 | H37: ='Financials FY'!L39 -> 0.12909174 | I37: ='Financials FY'!M39 -> 0.54310718 | J37: ='Financials FY'!N39 -> 0.093438368 | K37: ='Financials FY'!O39 -> 0.27168571 | ... M37: ='Financials FY'!Q39 -> 0.041294758 | P37: FCF/Debt | Q37: =M33/(M31+M30) -> 0.44011131 | S37: Intangible Assets | T37: =F3 -> 0 | U37: =G3 -> 8727868 | V37: =H3 -> 53986552 | W37: =I3 -> 757571799 | X37: =J3 -> 1578414353 | Y37: =K3 -> 7410742000 | Z37: =L3 -> 19944208 | AA37: =M3 -> 23630406
A38: Net book value | D38: ='Financials FY'!H71 -> 20112053 | E38: ='Financials FY'!I71 -> 11790662 | F38: ='Financials FY'!J71 -> 12311543 | G38: ='Financials FY'!K71 -> 14038405 | H38: ='Financials FY'!L71 -> 102795573 | I38: ='Financials FY'!M71 -> 1162729925 | J38: ='Financials FY'!N71 -> 2674849654 | K38: ='Financials FY'!O71 -> 11550071000 | L38: ='Financials FY'!P71 -> 29924703 | M38: ='Financials HY'!I54 -> 27818259 | P38: Gross Margin % change | Q38: =(M7/M16-I7/I16)/(I7/I16) -> 0 | S38: Short-term debt | T38: =F30 -> 390267 | U38: =G30 -> 489995 | V38: =H30 -> 7191467 | W38: =I30 -> 9713506 | X38: =J30 -> 167426274 | Y38: =K30 -> 1138874000 | Z38: =L30 -> 456160 | AA38: =M30 -> 1880547
A39: Invested Capital | C39: ='Financials FY'!G138 -> 0 | D39: ='Financials FY'!H138 -> 19966248 | E39: ='Financials FY'!I138 -> 11498024 | F39: ='Financials FY'!J138 -> 12237110 | G39: ='Financials FY'!K138 -> 14143433 | H39: ='Financials FY'!L138 -> 87694710 | I39: ='Financials FY'!M138 -> 1129705127 | J39: ='Financials FY'!N138 -> 2500230098 | ... M39: ='Financials FY'!Q138 -> 23375982 | P39: Gross Profit/Total Assets % change | Q39: =((I7/(I32+I24))-(G7/(G32+G24)))/(G7/(G32+G24)) -> 4.7472463 | S39: Long-term debt | T39: =F31 -> 315567 | U39: =G31 -> 1409130 | V39: =H31 -> 3818246 | W39: =I31 -> 11434433 | X39: =J31 -> 40379961 | Y39: =K31 -> 0 | Z39: =L31 -> 0 | AA39: =M31 -> 0
A40: EPS | E40: =E14/E18 -> -0.0037867788 | F40: =F14/F18 -> -0.012720733 | G40: =G14/G18 -> -0.01507825 | H40: =H14/H18 -> 0.039314225 | I40: =I14/I18 -> 0.63657709 | J40: =J14/J18 -> 2.1776548 | K40: =K14/K18 -> 14.013685 | L40: =L14/L18 -> 0.051316055 | M40: =M14/M18 -> 0.031540465 | P40: ROIC % change | Q40: =((M10*(1-M37)/M36)-(I10*(1-I37)/I36))/(I10*(1-I37)/I36) -> -0.83472463 | S40: Non Current Liabilities | T40: =F26 -> 1566298 | U40: =G26 -> 3188102 | V40: =H26 -> 18181525 | W40: =I26 -> 258841370 | X40: =J26 -> 544495477 | Y40: =K26 -> 3029134000 | Z40: =L26 -> 7556664 | AA40: =M26 -> 7861646
...

Sheet Financials FY
A1: INCOME STATEMENT | B1: Dec | C1: Dec | D1: Dec | E1: Dec | F1: Dec | G1: Dec | H1: Dec | I1: Dec | J1: Dec | K1: Dec | L1: Dec | M1: Dec | N1: Dec | O1: Dec | P1: Dec | Q1: Dec
A2: Turnover | B2: 2008 | C2: 2009 | D2: 2010 | E2: 2011 | F2: 2012 | G2: 2013 | H2: 2014 | I2: 2015 | J2: 2016 | K2: 2017 | L2: 2018 | M2: 2019 | N2: 2020 | O2: 2021 | P2: 2022 | Q2: 2023
A3: Revenue | H3: 14848743 | I3: 10039549 | J3: 19139918 | K3: 27451196 | L3: 248549590 | M3: 1498657461 | N3: 8390738256 | O3: 25284481000 | P3: =49818414 -> 49818414 | Q3: =53834005 -> 53834005
A4: Cost of sales | K4: -23254004 | L4: =L3-L5 -> 248549590
A5: Gross Profit | H5: =H3+H4 -> 14848743 | I5: =I3+I4 -> 10039549 | J5: =J3+J4 -> 19139918 | K5: =K3+K4 -> 4197192 | L5: =L3*P4 -> 0 | M5: =M3 -> 1498657461 | N5: =N3 -> 8390738256 | O5: =O3 -> 25284481000 | P5: =P3 -> 49818414 | Q5: =Q3 -> 53834005
A6: Profit before depriciation and fair value adjustments | H6: =244933 -> 244933 | I6: =245467 -> 245467 | L6: 20216067 | M6: 477331786 | N6: 1729386061 | O6: 5403401000 | P6: 14179147 | Q6: 12579230
A7: Depriciation | H7: =1156370 -> 1156370 | I7: =1126745 -> 1126745 | L7: -8619616 | M7: -74600618 | N7: -161998341 | O7: -739978000 | P7: -1812097 | Q7: -4342126
A8: Other operating income | I8: 197995 | J8: 361927 | K8: 612322
A9: Administration expenses | I9: -2924929 | J9: -3047099 | K9: -3558397
A10: Operating profit | H10: -936437 | I10: =SUM(I6:I9) -> -1354722 | J10: =SUM(J6:J9) -> -2685172 | K10: =SUM(K6:K9) -> -2946075 | L10: =SUM(L6:L9) -> 11596451 | M10: =SUM(M6:M9) -> 402731168 | N10: =SUM(N6:N9) -> 1567387720 | O10: =SUM(O6:O9) -> 4663423000 | P10: =SUM(P6:P9) -> 12367050 | Q10: =SUM(Q6:Q9) -> 8237104
A11: Share of profit from joint venture | I11: 12715 | J11: 22687
A12: Fair value adjustments | H12: =-25000 -> -25000 | I12: =-347807 -> -347807 | K12: 40500 | M12: 164798251 | N12: 43635647 | O12: 1321803000 | P12: 4570270 | Q12: 2200
A13: Net interest paid | L13: -1070216 | M13: -4265353 | N13: -12987289 | O13: -338789000 | P13: -245616 | Q13: -363607
A14: Net monetory loss | M14: -226574135 | N14: -1017558893 | O14: -996715000 | P14: -3403309
A15: Interest received | I15: 4438 | J15: 86302
A16: Finance costs | H16: -344253 | I16: -82569 | J16: -39621 | K16: -117448
A17: Income Before Tax (EBT) | H17: =SUM(H10:H16) -> -1305690 | I17: =SUM(I10:I16) -> -1767945 | J17: =SUM(J10:J16) -> -2615804 | K17: =SUM(K10:K16) -> -3023023 | L17: =SUM(L10:L16) -> 10526235 | M17: =SUM(M10:M16) -> 336689931 | N17: =SUM(N10:N16) -> 580477185 | O17: =SUM(O10:O16) -> 4649722000 | ... Q17: =SUM(Q10:Q16) -> 7875697
A18: Tax | H18: 272386 | I18: 932984 | J18: -189038 | K18: -475431 | L18: -1358850 | M18: -182858718 | N18: -54238841 | O18: -1263263000 | P18: -887680 | Q18: -325225
A19: Profit from continuing operations | H19: =H17+H18 -> -1033304 | I19: =I17+I18 -> -834961 | J19: =J17+J18 -> -2804842 | K19: =K17+K18 -> -3498454 | L19: =L17+L18 -> 9167385 | M19: =M17+M18 -> 153831213 | N19: =N17+N18 -> 526238344 | O19: =O17+O18 -> 3386459000 | ... Q19: =Q17+Q18 -> 7550472 | S19: =Q19/Q3 -> 0.1402547
A20: Profit from discontinued operations | H20: 455881 | I20: 203403
A21: Profit for the year | H21: =SUM(H19:H20) -> -577423 | I21: =SUM(I19:I20) -> -631558 | J21: =SUM(J19:J20) -> -2804842 | K21: =SUM(K19:K20) -> -3498454 | L21: =SUM(L19:L20) -> 9167385 | M21: =SUM(M19:M20) -> 153831213 | N21: =SUM(N19:N20) -> 526238344 | O21: =SUM(O19:O20) -> 3386459000 | ... Q21: =SUM(Q19:Q20) -> 7550472
A22: Other comprehensive income | I22: 520318 | J22: 610729 | K22: 1077972 | L22: 10354583 | M22: 40747176
A23: Total comprehensive income | I23: =I21+I22 -> -111240 | J23: =J21+J22 -> -2194113 | K23: =K21+K22 -> -2420482 | L23: =L21+L22 -> 19521968 | M23: =M21+M22 -> 194578389 | N23: =N21+N22 -> 526238344 | O23: =O21+O22 -> 3386459000 | P23: =P21+P22 -> 12400715 | Q23: =Q21+Q22 -> 7550472
A25: Basic income attributable to owners of parent | H25: =H27-H26 -> -1033304 | I25: =I27-I26 -> -834961 | J25: =J27-J26 -> -2804842 | K25: =K27-K26 -> -3498454 | L25: =L27-L26 -> 9167385 | M25: =M27-M26 -> 153831213 | N25: =N27-N26 -> 526238344 | O25: =O27-O26 -> 3386459000 | ... Q25: =Q27-Q26 -> 7550472
A26: Non controlling interests
A27: Income attributable to shareholders | H27: =H19 -> -1033304 | I27: =I19 -> -834961 | J27: =J19 -> -2804842 | K27: =K19 -> -3498454 | L27: =L19 -> 9167385 | M27: =M19 -> 153831213 | N27: =N19 -> 526238344 | O27: =O19 -> 3386459000 | ... Q27: =Q19 -> 7550472
A29: Basic income attributable to owners of parent
A30: Comprehensive income attributable to owners of parent | H30: =H32-H31 -> -577423 | I30: =I32-I31 -> -111240 | J30: =J32-J31 -> -2194113 | K30: =K32-K31 -> -2420482 | L30: =L32-L31 -> 19521968 | M30: =M32-M31 -> 194578389 | N30: =N32-N31 -> 526238344 | O30: =O32-O31 -> 3386459000 | ... Q30: =Q32-Q31 -> 7550472
A31: Non controlling interests
A32: Income attributable to shareholders | H32: =H21+H22 -> -577423 | I32: =I23 -> -111240 | J32: =J23 -> -2194113 | K32: =K23 -> -2420482 | L32: =L23 -> 19521968 | M32: =M23 -> 194578389 | N32: =N23 -> 526238344 | O32: =O23 -> 3386459000 | P32: =P23 -> 12400715 | Q32: =Q23 -> 7550472
A34: Basic Earnings per share | H34: =H25/H131*100 -> #DIV/0! | I34: =I25/I131*100 -> -0.37867788 | J34: =J25/J131*100 -> -1.2720733 | K34: =K30/K131*100 -> -1.0432218 | L34: =L30/L131*100 -> 8.3719734 | M34: =M30/M131*100 -> 80.519513 | N34: =N30/N131*100 -> 217.76548 | O34: =O30/O131*100 -> 1401.3685 | P34: =P30/P131*100 -> 5.1316055 | Q34: =Q30/Q131*100 -> 3.1540465
A35: Headline earnings per share | L35: 3.86 | M35: 11.81 | N35: 11.81 | O35: 11.81 | P35: =P30/P131*100 -> 5.1316055 | Q35: =Q30/Q131*100 -> 3.1540465
A36: Diluted earnings per share | H36: =H30/H131*100 -> #DIV/0! | I36: =I30/I131*100 -> -0.050450414 | J36: =J30/J131*100 -> -0.99509087 | K36: =K30/K131*100 -> -1.0432218 | L36: =L30/L131*100 -> 8.3719734 | M36: =M30/M131*100 -> 80.519513 | N36: =N30/N131*100 -> 217.76548 | O36: =O30/O131*100 -> 1401.3685 | ... Q36: =Q30/Q131*100 -> 3.1540465
A37: Dividends
A38: http://www.aranca.com/about-aranca
A39: Tax rate | H39: =-I18/H17 -> 0.71455246 | I39: =-I18/I17 -> 0.5277223 | J39: =-J18/J17 -> -0.072267647 | K39: =-K18/K17 -> -0.15727006 | L39: =-L18/L17 -> 0.12909174 | M39: =-M18/M17 -> 0.54310718 | N39: =-N18/N17 -> 0.093438368 | O39: =-O18/O17 -> 0.27168571 | P39: =-P18/P17 -> 0.066801145 | Q39: =-Q18/Q17 -> 0.041294758
A40: BALANCE SHEET | H40: =H1 -> Dec | I40: =I1 -> Dec | J40: =J1 -> Dec | K40: =K1 -> Dec | L40: =L1 -> Dec | M40: =M1 -> Dec | N40: =N1 -> Dec | O40: =O1 -> Dec | ... Q40: =Q1 -> Dec
H41: =H2 -> 2014 | I41: =I2 -> 2015 | J41: =J2 -> 2016 | K41: =K2 -> 2017 | L41: =L2 -> 2018 | M41: 2019 | N41: 2020 | O41: 2021 | P41: 2022 | Q41: 2023
A42: PPE | H42: 11792693 | I42: 6004892 | J42: 6731970 | K42: 8727868 | L42: 53986552 | M42: 757571799 | N42: 1578414353 | O42: 7410742000 | P42: 19944208 | Q42: 23630406
A43: Deferred tax asset
...

Sheet DCF
L2: (Interim) | M2: Year 1 | N2: Year 2-10 | O2: Beyond 10
A3: Fiscal Year | B3: 2013 | C3: 2015 | D3: 2016 | E3: 2017 | F3: 2018 | G3: 2019 | H3: 2020 | I3: 2021 | J3: 2022 | K3: 2023
A5: Sales | B5: =(K5/C5)^(1/5)-1 -> 0.3991636 | C5: ='Financials FY'!I3 -> 10039549 | D5: ='Financials FY'!J3 -> 19139918 | E5: ='Financials FY'!K3 -> 27451196 | F5: ='Financials FY'!L3 -> 248549590 | G5: ='Financials FY'!M3 -> 1498657461 | H5: ='Financials FY'!N3 -> 8390738256 | I5: ='Financials FY'!O3 -> 25284481000 | J5: ='Financials FY'!P3 -> 49818414 | K5: ='Financials FY'!Q3 -> 53834005 | L5: ='Financials HY'!I3 -> 31510454 | M5: =K5*(1+M6) -> 57112496
A6: Sales growth | D6: =(D5-C5)/C5 -> 0.90645197 | E6: =(E5-D5)/D5 -> 0.43423791 | F6: =(F5-E5)/E5 -> 8.0542354 | G6: =(G5-F5)/F5 -> 5.0296115 | H6: =(H5-G5)/G5 -> 4.5988366 | I6: =(I5-H5)/H5 -> 2.0133798 | J6: =(J5-I5)/I5 -> -0.99802968 | K6: =(K5-J5)/J5 -> 0.080604553 | L6: =('Financials HY'!I3-'Financials HY'!H3)/'Financials HY'!H3 -> 0.30483792 | M6: =(1+Q6)*(1+Q7)-1 -> 0.0609 | N6: 0.08 | O6: 0.07 | P6: Inflation | Q6: 0.03
A7: EBIT | C7: ='Financials FY'!I10 -> -1354722 | D7: ='Financials FY'!J10 -> -2685172 | E7: ='Financials FY'!K10 -> -2946075 | F7: ='Financials FY'!L10 -> 11596451 | G7: ='Financials FY'!M10 -> 402731168 | H7: ='Financials FY'!N10 -> 1567387720 | I7: ='Financials FY'!O10 -> 4663423000 | J7: ='Financials FY'!P10 -> 12367050 | K7: ='Financials FY'!Q10 -> 8237104 | L7: ='Financials HY'!I13 -> 5036750 | P7: order book | Q7: 0.03
A8: EBIT Margin | C8: =C7/C5 -> -0.13493853 | D8: =D7/D5 -> -0.14029172 | E8: =E7/E5 -> -0.10732046 | F8: =F7/F5 -> 0.046656488 | G8: =G7/G5 -> 0.26872796 | H8: =H7/H5 -> 0.18679974 | I8: =I7/I5 -> 0.18443815 | J8: =J7/J5 -> 0.24824255 | ... L8: =L7/L5 -> 0.15984378 | M8: 0.15 | N8: 0.15 | O8: 0.15
A9: Invested Capital | B9: =(K9/C9)^(1/5)-1 -> 0.15246921 | C9: ='Financials FY'!I138 -> 11498024 | D9: ='Financials FY'!J138 -> 12237110 | E9: ='Financials FY'!K138 -> 14143433 | F9: ='Financials FY'!L138 -> 87694710 | G9: ='Financials FY'!M138 -> 1129705127 | H9: ='Financials FY'!N138 -> 2500230098 | I9: ='Financials FY'!O138 -> 6640641000 | J9: ='Financials FY'!P138 -> 28842849 | K9: ='Financials FY'!Q138 -> 23375982
A10: Sales/Capital | B10: =AVERAGE(C10:D10) -> 1.2186212 | C10: =C5/C9 -> 0.87315429 | D10: =D5/D9 -> 1.5640881 | E10: =E5/E9 -> 1.9409146 | F10: =F5/F9 -> 2.8342598 | G10: =G5/G9 -> 1.3265917 | H10: =H5/H9 -> 3.3559864 | I10: =I5/I9 -> 3.8075362 | J10: =J5/J9 -> 1.7272362 | K10: =K5/K9 -> 2.3029623 | M10: 0.05 | N10: 0.05 | O10: 0.05
A11: Return on Capital | C11: =C7*(1-'Financials FY'!I39)/C9 -> -0.055644778 | D11: =D7*(1-'Financials FY'!J39)/D9 -> -0.2352862 | E11: =E7*(1-'Financials FY'!K39)/E9 -> -0.24105918 | F11: =F7*(1-'Financials FY'!L39)/F9 -> 0.11516595 | G11: =G7*(1-'Financials FY'!M39)/G9 -> 0.16287877 | H11: =H7*(1-'Financials FY'!N39)/H9 -> 0.56832112 | I11: =I7*(1-'Financials FY'!O39)/I9 -> 0.51146232 | J11: =J7*(1-'Financials FY'!P39)/J9 -> 0.40013096 | K11: =K7*(1-'Financials FY'!Q39)/K9 -> 0.33782345 | O11: 0.15
A12: Cost of Capital | M12: =WACC -> 0.13379251 | N12: 0.12 | O12: 0.12
A13: Ebit Growth | D13: =(D7-C7)/C7 -> 0.98208341 | E13: =(E7-D7)/D7 -> 0.097164353 | F13: =(F7-E7)/E7 -> -4.9362375 | G13: =(G7-F7)/F7 -> 33.728829 | H13: =(H7-G7)/G7 -> 2.8918957 | I13: =(I7-H7)/H7 -> 1.9752836 | J13: =(J7-I7)/I7 -> -0.99734807 | K13: =(K7-J7)/J7 -> -0.33394755
B15: 2023 | C15: 2024 | D15: 2025 | E15: 2026 | F15: 2027 | G15: 2028 | H15: 2029 | I15: 2030 | J15: 2031 | K15: 2032 | L15: Terminal year
A16: Revenue | B16: =M5 -> 57112496 | C16: =B16*(1+$N$6) -> 61681496 | D16: =C16*(1+$N$6) -> 66616015 | E16: =D16*(1+$N$6) -> 71945296 | F16: =E16*(1+$N$6) -> 77700920 | G16: =F16*(1+$N$6) -> 83916994 | H16: =G16*(1+$N$6) -> 90630353 | I16: =H16*(1+$N$6) -> 97880782 | J16: =I16*(1+$N$6) -> 1.0571124e+08 | K16: =J16*(1+$N$6) -> 1.1416814e+08 | L16: =K16*(1+$O$6) -> 1.2215991e+08
A17: EBIT | B17: =B16*M8 -> 8566874.4 | C17: =C16*$N$8 -> 9252224.3 | D17: =D16*$N$8 -> 9992402.3 | E17: =E16*$N$8 -> 10791794 | F17: =F16*$N$8 -> 11655138 | G17: =G16*$N$8 -> 12587549 | H17: =H16*$N$8 -> 13594553 | I17: =I16*$N$8 -> 14682117 | J17: =J16*$N$8 -> 15856687 | K17: =K16*$N$8 -> 17125222 | L17: =L16*$O$6 -> 8551194
A18: EBIT(1-t) | B18: =B17*(1-0.2475) -> 6446573 | C18: =C17*(1-0.2475) -> 6962298.8 | D18: =D17*(1-0.2475) -> 7519282.7 | E18: =E17*(1-0.2475) -> 8120825.3 | F18: =F17*(1-0.2475) -> 8770491.4 | G18: =G17*(1-0.2475) -> 9472130.7 | H18: =H17*(1-0.2475) -> 10229901 | I18: =I17*(1-0.2475) -> 11048293 | ... L18: =L17*(1-0.2475) -> 6434773.5
A19: Reinvestment | B19: =B16*M10 -> 2855624.8 | C19: =C16*$N$10 -> 3084074.8 | D19: =D16*$N$10 -> 3330800.8 | E19: =E16*$N$10 -> 3597264.8 | F19: =F16*$N$10 -> 3885046 | G19: =G16*$N$10 -> 4195849.7 | H19: =H16*$N$10 -> 4531517.7 | I19: =I16*$N$10 -> 4894039.1 | J19: =J16*$N$10 -> 5285562.2 | K19: =K16*$N$10 -> 5708407.2 | L19: =L16*O10 -> 6107995.7
A20: FCF | B20: =B18-B19 -> 3590948.2 | C20: =C18-C19 -> 3878224 | D20: =D18-D19 -> 4188482 | E20: =E18-E19 -> 4523560.5 | F20: =F18-F19 -> 4885445.4 | G20: =G18-G19 -> 5276281 | H20: =H18-H19 -> 5698383.5 | I20: =I18-I19 -> 6154254.1 | ... L20: =L18-L19 -> 326777.77
A21: Discount rate | B21: =1+M12 -> 1.1337925 | C21: =B21*(1+N12) -> 1.2698476 | D21: =C21*(1+$O$12) -> 1.4222293 | E21: =D21*(1+$O$12) -> 1.5928968 | F21: =E21*(1+$O$12) -> 1.7840445 | G21: =F21*(1+$O$12) -> 1.9981298 | H21: =G21*(1+$O$12) -> 2.2379054 | I21: =H21*(1+$O$12) -> 2.506454 | J21: =I21*(1+$O$12) -> 2.8072285 | K21: =J21*(1+$O$12) -> 3.1440959 | L21: =K21*(1+$O$12) -> 3.5213874
A22: Reinvestment rate | B22: =B19/B18 -> 0.44296788 | C22: =C19/C18 -> 0.44296788 | D22: =D19/D18 -> 0.44296788 | E22: =E19/E18 -> 0.44296788 | F22: =F19/F18 -> 0.44296788 | G22: =G19/G18 -> 0.44296788 | H22: =H19/H18 -> 0.44296788 | I22: =I19/I18 -> 0.44296788 | ... K22: =K19/K18 -> 0.44296788 | L22: =O6/L24 -> 0.77075775
A23: Invested Capital | B23: =K9+B19 -> 26231607 | C23: =B23+C19 -> 29315682 | D23: =C23+D19 -> 32646482 | E23: =D23+E19 -> 36243747 | F23: =E23+F19 -> 40128793 | G23: =F23+G19 -> 44324643 | H23: =G23+H19 -> 48856161 | I23: =H23+I19 -> 53750200 | J23: =I23+J19 -> 59035762 | ... L23: =K23+L19 -> 70852165
A24: ROIC | B24: =B18/B23 -> 0.24575593 | C24: =C18/C23 -> 0.23749401 | D24: =D18/D23 -> 0.23032444 | E24: =E18/E23 -> 0.22406142 | F24: =F18/F23 -> 0.21855856 | G24: =G18/G23 -> 0.21369897 | H24: =H18/H23 -> 0.20938815 | I24: =I18/I23 -> 0.20554888 | ... L24: =L18/L23 -> 0.090819716
L25: =L20/(O12-O6) -> 6535555.4
A26: FCF | B26: =B20/B21 -> 3167200.5 | C26: =C20/(1+C21) -> 1708583.4 | D26: =D20/(1+D21) -> 1729184.7 | E26: =E20/(1+E21) -> 1744597.2 | F26: =F20/(1+F21) -> 1754801.5 | G26: =G20/(1+G21) -> 1759857.4 | H26: =H20/(1+H21) -> 1759898.1 | I26: =I20/(1+I21) -> 1755121.9 | J26: =J20/(1+J21) -> 1745782.9 | K26: =K20/(1+K21) -> 1732180.5 | L26: =L25/L21 -> 1855960.3
A30: Calculation
A31: Terminal value | C31: =L26 -> 1855960.3
A32: Present Value | C32: =SUM(B26:K26) -> 18857208
A33: Excess Cash | C33: ='Financials HY'!I38 -> 2165459
A34: Investments | C34: ='Financials HY'!I29 -> 44688
A35: Interest Bearing Debt | C35: =-('Financials HY'!I64) -> -1265615
A36: Minority interest | C36: ='Financials HY'!D53 -> 0
A38: Present Value | C38: =SUM(C31:C36) -> 21657700
A39: Shares Outstanding | C39: 239390000 | F39: =28000000 -> 28000000
A40: Per Share Value Usc | C40: =C38/C39*100 -> 9.0470364 | F40: =F39/C39 -> 0.11696395
A41: Current Price Usc | C41: =298/25.28 -> 11.787975
A42: Margin of Safety | C42: =1-(C41/C40) -> -0.30296532 | F42: 16089596
F43: =300000000 -> 300000000
F44: =F42/F43 -> 0.053631987

Sheet WACC
B2: The standard procedure for estimating betas is to regress stock returns (Rj) against market returns (Rm) -
B4: Rj = a + b Rm
B5: where a is the intercept and b is the slope of the regression.
C6: or
B13: Damodaran Estimate of ERP | E13: 0.18
B14: Our estimate | E14: 0.14 | F14: A large part of Damodaran's estimate has to do with currency risk which does not fully apply for a domestic investor
B15: Re= rf+(rm-rf)*ß
B17: rm | C17: 0.15 | D17: market return
B18: Re | D18: required rate of return on equity/ cost of equity
B19: rf | C19: 0.18 | D19: risk free rate= usually refers to return you earn from investing in risk free instruments such as treasury bills
B20: rm-rf | C20: =C17-C19 -> -0.03 | D20: market risk premium
B21: ß | C21: 1 | D21: beta coefficient =unsystemic risk. Refers to the extent to which a stock reacts to the market as a whole
B23: Re | C23: =C19+(C20)*C21 -> 0.15
B27: Prevailing share price
B29: WACC=(E/V)*Re+D/V*Rd(1-Tc)
B31: Re | C31: 0.14 | D31: cost of equity
B32: Rd | C32: 0.1 | D32: cost of debt
B33: E | C33: ='Financials HY'!I75 -> 22232141 | D33: market value of the firm's equity
B34: D | C34: =-DCF!C35 -> 1265615 | D34: market value of the firm's debt
B35: V | C35: =C33+C34 -> 23497756 | D35: E+D
B36: Tc | C36: 0.2475 | D36: Corporate tax
B37: E/V | C37: =C33/C35 -> 0.9461389
B38: D/V | C38: =C34/C35 -> 0.053861101
B40: WACC | C40: =C37*C31+C38*(C32*C36) -> 0.13379251

Sheet Key Factors
A2: 1 | B2: Falling operational margins from 275 to 19%
A3: 2 | B3: $108m net cash position
A4: 3
A5: 4

Sheet Ratings
A2: STOCK RATING
A5: Strong Buy | B5: x>80
A6: Buy | B6: 80<x<65
A7: Hold | B7: 65<x<50 | D7: =D17 -> #DIV/0!
A8: Sell | B8: 50<x<35
A9: Strong Sell | B9: x<35
B12: Weighting | C12: Raw Score | D12: Weighted Score
A13: Valuation | B13: 0.6 | C13: =G41 -> 4.75 | D13: =C13*B13/10 -> 0.285
A14: Quality | B14: 0.2 | C14: =E85 -> #DIV/0! | D14: =C14*B14/10 -> #DIV/0!
A15: Growth | B15: 0.15 | C15: =E65 -> 2.65 | D15: =C15*B15/10 -> 0.03975
A16: Analyst Opinion | B16: 0.05 | C16: =C26 -> 6 | D16: =C16*B16/10 -> 0.03
A17: Total | B17: =SUM(B13:B16) -> 1 | C17: =SUM(C13:C16) -> #DIV/0! | D17: =SUM(D13:D16) -> #DIV/0!
E20: 0.8
E21: 0.65
A22: ANALYST OPINION (10) | B22: Max possible | C22: Score | E22: 0.5
A23: Above inflation pricing power for goods and services | B23: 10 | C23: 7 | E23: 0.35
A24: Earnings stability as shown by last 4years | B24: 10 | C24: 5
A25: Market sentiment on the company | B25: 10 | C25: 6
A26: Total | B26: =SUM(B23:B25) -> 30 | C26: =AVERAGE(C23:C25) -> 6
A32: VALUATION (40) | B32: Current price | C32: Estimated Price | D32: Differential | E32: Scoring | F32: Weighting | G32: Points
A33: DCF | B33: ='Data Input'!Q6 -> 11 | C33: ='Data Input'!Q5 -> 1.0869176 | D33: =(C33-B33)/B33 -> -0.90118931 | E33: =IF((D33>=50%),C45,IF(D33>=20%,C46,IF(D33>=10%,C47,IF(D33>=5%,C48,IF(D33>=0%,C49,IF(D33>=-5%,C50,IF(D33>=-15%,C51,IF(D33<=-15%,C52)))))))) -> 2 | F33: 0.6 | G33: =F33*E33 -> 1.2
A34: EBIT Valuation
B35: Current Valuation | C35: Fair Valuation / Industry average
A36: Price/NAV | B36: ='Data Input'!Q9 -> 1.0869176 | C36: 3 | D36: =(C36-B36)/B36 -> 1.7600988 | E36: =IF((D36>=50%),C45,IF(D36>=20%,C46,IF(D36>=10%,C47,IF(D36>=5%,C48,IF(D36>=0%,C49,IF(D36>=-5%,C50,IF(D36>=-15%,C51,IF(D36<=-15%,C52)))))))) -> 10 | F36: 0.1 | G36: =F36*E36 -> 1
A37: EV/EBIT | B37: ='Data Input'!Q10 -> 2.5897812 | C37: 5 | D37: =(C37-B37)/B37 -> 0.93066503 | E37: =IF((D37>=50%),C45,IF(D37>=20%,C46,IF(D37>=10%,C47,IF(D37>=5%,C48,IF(D37>=0%,C49,IF(D37>=-5%,C50,IF(D37>=-15%,C51,IF(D37<=-15%,C52)))))))) -> 10 | F37: 0.05 | G37: =F37*E37 -> 0.5
A38: P/E (F) | B38: ='Data Input'!Q8 -> 3.4875833 | C38: 30 | D38: =(C38-B38)/B38 -> 7.6019451 | E38: =IF((D38>=50%),C45,IF(D38>=20%,C46,IF(D38>=10%,C47,IF(D38>=5%,C48,IF(D38>=0%,C49,IF(D38>=-5%,C50,IF(D38>=-15%,C51,IF(D38<=-15%,C52)))))))) -> 10 | F38: 0.1 | G38: =F38*E38 -> 1
A39: P/E/P/E(F) | B39: ='Data Input'!Q7/'Data Input'!Q8 -> 1 | D39: =B39 -> 1 | E39: =IF((D39>=3),C45,IF(D39>=2,C46,IF(D39>=1.5,C47,IF(D39>=1,C48,IF(D39>=0.8,C49,IF(D39>=5,C50,IF(D39>=0.2,C51,IF(D39<=-1,C52)))))))) -> 7 | F39: 0.15 | G39: =F39*E39 -> 1.05
A41: Total | F41: =SUM(F33:F40) -> 1 | G41: =SUM(G33:G40) -> 4.75
A44: Margin of Safety | B44: Valuation Differential
B45: >50% | C45: 10
B46: 20%<x<50% | C46: 9
B47: 10%<x<20% | C47: 8
B48: 5%<x<10% | C48: 7
B49: 0%<x<5% | C49: 6
B50: 0%<x<-5% | C50: 4
B51: *-5%<x<-15% | C51: 3
B52: *-15%>x | C52: 2
A55: GROWTH (20) | B55: Relative Weighting | C55: Growth % | D55: Scoring | E55: Weighted Scoring
A56: Net profit growth | B56: 0.25 | C56: ='Data Input'!Q12 -> -0.95091717 | D56: =IF((C56>=50%),H56,IF(C56>=20%,H57,IF(C56>=10%,H58,IF(C56>=5%,H59,IF(C56>=0%,H60,IF(C56>=-5%,H61,IF(C56>=-15%,H62,IF(C56<=-15%,H63)))))))) -> 2 | E56: =D56*B56 -> 0.5 | G56: >50% | H56: 10
A57: Net profit growth (F) | B57: 0.1 | C57: ='Data Input'!Q13 -> 0 | D57: =IF((C57>=50%),H56,IF(C57>=20%,H57,IF(C57>=10%,H58,IF(C57>=5%,H59,IF(C57>=0%,H60,IF(C57>=-5%,H61,IF(C57>=-15%,H62,IF(C57<=-15%,H63)))))))) -> 6 | E57: =D57*B57 -> 0.6 | G57: 20%<x<50% | H57: 9
...

Sheet Notes
P3: Description | Q3: 1997 | R3: 2023
P4: Exchange rate 1997 | Q4: 6 | R4: 6000
P5: Mkt cap ZWL | Q5: =1000000000 -> 1000000000 | R5: 220003000000
P6: Mkt cap june usd | Q6: =Q5/6 -> 1.6666667e+08 | R6: 44000000
E7: 2022 order book: US$214 Million
E8: Share buy back approved in May 2020 | P8: Revenue 1997 ZWL | Q8: 515660000 | R8: =DCF!K5 -> 53834005
E9: in 2021 over 17% of the admin expenses were absorbed by Bank charges only | P9: Revenue usd | Q9: =Q8/6 -> 85943333 | R9: =R8/1000 -> 53834.005
E10: The company has 23 ongoing projects
E11: Top 3 directors collectively owned 98 million shares OUT OF 241.65 million outstanding shares, that’s 40%. | P11: Share price zwl | Q11: 24 | R11: 856.75
C12: Top shareholders | E12: 1 | F12: Zumbani Capital- 2 white guys | H12: 0.2827 | P12: Share price USD | Q12: =Q11/6 -> 4 | R12: =R11/6000 -> 0.14279167
E13: 4 | F13: Giona Capital- Malunga | H13: 0.0767
E14: 6 | F14: Amalgamated Africa- Paddy | H14: 0.0453
P15: Number of shares | Q15: =41566870 -> 41566870 | R15: =DCF!C39 -> 239390000
E16: Masimba is owened by Management | P16: %ge change | Q16: 0 | R16: =(R15-Q15)/Q15 -> 4.7591539
